Accepted connection from ('127.0.0.1', 36556)
Closing connection to ('127.0.0.1', 36556)
Accepted connection from ('127.0.0.1', 36562)
Closing connection to ('127.0.0.1', 36562)
Accepted connection from ('127.0.0.1', 49402)
Closing connection to ('127.0.0.1', 49402)
Closing connection to ('127.0.0.1', 49402)
Closing connection to ('127.0.0.1', 49402)
Traceback (most recent call last):
  File "/home/involuntary/Documents/school stuff/EPQ/MyWebapp/challenges/Cryptography/Deeper in the catacombs/deeperInTheCatacombs.py", line 246, in service_connection
    sock.send(" - Generating your public / private key-pairs now . . .\n".encode("utf-8"))
OSError: [Errno 9] Bad file descriptor

During handling of the above exception, another exception occurred:

Traceback (most recent call last):
  File "/home/involuntary/Documents/school stuff/EPQ/MyWebapp/challenges/Cryptography/Deeper in the catacombs/deeperInTheCatacombs.py", line 298, in <module>
    service_connection(key, mask)
  File "/home/involuntary/Documents/school stuff/EPQ/MyWebapp/challenges/Cryptography/Deeper in the catacombs/deeperInTheCatacombs.py", line 280, in service_connection
    userData.pop(key.data.addr[1])
KeyError: 49402
[?1049h[22;0;0t[1;24r(B[m[4l[?7h[H[2J[7Ginvoluntary-HP-ENVY-x360-2-in-1-Laptop-15-ey0xxx: Sat Jun 28 08:06:33 2025[3;1Hhello[24;80H[24;1H[?1049l[23;0;0t[?1l>[?1049h[22;0;0t[1;24r(B[m[4l[?7h[H[2J[7Ginvoluntary-HP-ENVY-x360-2-in-1-Laptop-15-ey0xxx: Sat Jun 28 08:06:40 2025[3;1Hhello[24;80H[1;75H5[24;80H[1;74H50[24;80H[1;75H5[24;80H[24;1H[?1049l[23;0;0t[?1l>